# Panic and Recover

In Go, **panic** and **recover** are low-level control flow mechanisms that disrupt the normal execution of a program. They allow you to handle unexpected situations (often errors or exceptional states) differently from the usual `error` handling approach. While the primary way to handle errors in Go is through multiple return values (`func foo() (Result, error)`), **panic** and **recover** provide a way to handle truly exceptional conditions or to abort a sequence of function calls. Below is an in-depth explanation of how panic and recover work, along with several illustrative examples.

---

## 1. Understanding Panic

1. **What is a Panic?**
    - A panic is similar to an exception in other languages.
    - Calling `panic(...)` immediately stops the normal flow of the goroutine.
    - Go will start **unwinding** the stack: it calls deferred functions in LIFO (last-in-first-out) order before ending the goroutine (and potentially the entire program).

2. **When to Use Panic**
    - Panics are usually reserved for severe issues in which normal error handling (`if err != nil`) isn’t feasible or meaningful.
    - Common usage:
        - Initialization failures in `init()` functions.
        - In certain library code when an unrecoverable scenario is encountered.
        - To indicate a bug or programmer error (e.g., an invalid invariant).

3. **Behavior**
    - If a goroutine panics and the panic is not recovered, the program prints the panic message and a stack trace, then exits.
    - If a `recover` call is encountered (in a deferred function) before exiting, it can catch the panic and return to normal execution flow.

---

## 2. Basic Panic Example

```go
package main

import "fmt"

func main() {
    fmt.Println("Before the panic")
    panic("Something went wrong!")
    fmt.Println("After the panic") // This will never run
}
```

### Explanation 1
- The program prints **"Before the panic"**, then calls `panic("Something went wrong!")`.
- The program unwinds the stack, skipping **"After the panic"**.
- A runtime error message along with a stack trace is displayed:
  ```
  panic: Something went wrong!
  
  goroutine 1 [running]:
  main.main()
      .../main.go:8 +0x...
  ```

---

## 3. Using Defer with Panic

When you trigger a panic, **all deferred functions** in the current goroutine will still run in **reverse order** of their definition. This gives you an opportunity to handle cleanup (e.g., closing files or network connections) even when a panic occurs.

### Example: Defer During Panic

```go
package main

import "fmt"

func main() {
    defer func() {
        fmt.Println("Deferred call 1")
    }()
    defer func() {
        fmt.Println("Deferred call 2")
    }()

    fmt.Println("Starting...")
    panic("Triggering a panic")

    fmt.Println("This line never executes")
}
```

### Explanation 2
1. The program prints **"Starting..."**.
2. `panic("Triggering a panic")` is called, causing the goroutine to begin unwinding.
3. Deferred functions run in reverse order: **"Deferred call 2"** then **"Deferred call 1"**.
4. Finally, the panic is still unhandled, so the program exits with a panic message.

**Sample Output**:
```
Starting...
Deferred call 2
Deferred call 1
panic: Triggering a panic
...
```

---

## 4. Recovering from a Panic

**Recover** is a built-in function that allows you to regain control of a panicking goroutine. It only works if called directly within a **deferred function**. If you call `recover()` outside of a deferred function, it returns `nil`.

1. **How Recover Works**
    - `recover()` returns the value passed to `panic()`.
    - If the goroutine is not panicking, `recover()` returns `nil`.
    - Once you recover from a panic, execution continues in the deferred function after `recover()`, and the function that caused the panic does not continue (i.e., it has already unwound to the point of the defer).

2. **When to Use Recover**
    - Typically used in libraries that need to intercept panics and translate them into error returns, or to keep the application running while logging critical information.

---

## 5. Recover Example

```go
package main

import "fmt"

func main() {
    fmt.Println("Main started")
    safeFunction()
    fmt.Println("Main ended gracefully")
}

func safeFunction() {
    defer func() {
        if r := recover(); r != nil {
            fmt.Println("Recovered from panic:", r)
        }
    }()

    fmt.Println("safeFunction: Doing something risky...")
    panic("An unexpected issue occurred!")
    fmt.Println("This line will never be reached")
}
```

### Explanation 3
1. `main` calls `safeFunction()`.
2. `safeFunction` defers an anonymous function that checks `recover()`.
3. When `panic("An unexpected issue occurred!")` is invoked, the deferred function runs.
4. `recover()` captures **"An unexpected issue occurred!"**, preventing the program from crashing.
5. After recovering, control returns to the end of `safeFunction`.
6. Execution continues in `main`, printing **"Main ended gracefully"**.

**Sample Output**:
```
Main started
safeFunction: Doing something risky...
Recovered from panic: An unexpected issue occurred!
Main ended gracefully
```

---

## 6. Multiple Panics and Nested Defers

Go handles only the **first** panic encountered during the unwinding unless you explicitly recover and re-panic. If a deferred function panics while already handling a panic, the runtime aborts with an error because it cannot handle multiple simultaneous panics.

### Example: Nested Panics

```go
package main

import "fmt"

func main() {
    defer func() {
        if r := recover(); r != nil {
            fmt.Println("Recovered in main:", r)
            // Attempt a second panic in the same defer
            // panic("Second panic") // Uncommenting this line leads to fatal error
        }
    }()

    panic("First panic")
}
```

### Explanation 4
1. `panic("First panic")` starts unwinding the stack.
2. The deferred function runs, calls `recover()`, and gets **"First panic"**.
3. If you attempt a second panic in the same deferred function, you’ll cause a fatal error because Go can’t handle two simultaneous panics during unwinding.

**Sample Output**:
```
Recovered in main: First panic
```

**If the second panic were uncommented**, you’d get:
```
fatal error: panic during panic
```
... and the program would crash.

---

## 7. Example: Converting Panics to Errors in a Library

A common pattern in Go libraries is to capture a panic, convert it to an error, and return that error to the caller. This way, the library never crashes the entire application with a panic unless it’s truly unrecoverable.

```go
package main

import (
    "fmt"
)

func main() {
    err := doOperation()
    if err != nil {
        fmt.Println("Operation failed with error:", err)
    } else {
        fmt.Println("Operation succeeded")
    }
}

func doOperation() (err error) {
    defer func() {
        if r := recover(); r != nil {
            err = fmt.Errorf("doOperation panic: %v", r)
        }
    }()

    riskyOperation()
    return nil
}

func riskyOperation() {
    panic("some unexpected condition")
}
```

### Explanation 5
1. `doOperation` uses a named return variable `err`.
2. If `r := recover()` is non-nil, `err` is set to a new `fmt.Errorf(...)`.
3. Because `err` is a named return variable, it’s returned automatically from `doOperation`.
4. In `main`, you handle the error just like any normal error check.

**Sample Output**:
```
Operation failed with error: doOperation panic: some unexpected condition
```

---

## 8. Best Practices

1. **Use Panic Sparingly**
    - Reserve panics for truly exceptional conditions or programmer errors (e.g., out-of-range indexes, violating invariants).

2. **Prefer Errors for Expected Failures**
    - For typical error conditions (e.g., file not found, invalid input), return an `error` instead of calling `panic`.

3. **Always Defer Recovery**
    - If you must handle a panic gracefully, place `recover()` in a deferred function.
    - Typically, you do this at an appropriate boundary (like in a top-level function or library boundary).

4. **One `recover` Catch**
    - Each panicking sequence can be recovered only once. If you need to escalate or rethrow the panic, re-panic after capturing it.

5. **Check for Data Corruption**
    - If your code panics due to a data consistency issue, even if you recover, be sure the application can continue safely.

---

## Conclusion

Panic and recover provide a mechanism for handling unexpected conditions or programmer errors by unwinding the stack. You typically rely on them for critical or non-recoverable scenarios and convert them into `error` returns for library boundaries. The combination of `panic`, `defer`, and `recover` ensures your program can clean up resources and possibly continue running when feasible. However, they are not substitutes for regular error handling. In practice, most Go code uses explicit `error` checks, reserving panic for truly exceptional or unrecoverable situations.